Workbook

Sheet Pay Calculator
A1: PAY CALCULATOR
A2: Fortnightly pay · tax · super — QLD OO stream | edit the blue-on-yellow cells, everything else is automatic
A3: =IF(TODAY()>RatesValidUntil,"⚠ RATES MAY BE OUT OF DATE — checked good to "&TEXT(RatesValidUntil,"d mmm yyyy")&". See Settings & Rates → block E for what is due.","")
A4: ① PROFILE & SETTINGS
A5: Employment type | B5: Permanent | D5: Permanent / Casual — sets the rate column & the member-super default
A6: Classification | B6: L3-4 | C6: =IF(OR($B$6="Custom",$B$6=""),"",IFERROR(INDEX(PayScaleRates,MATCH($B$6,PayScaleNames,0),IF($B$5="Casual",2,1)),"")) -> 37.5 | E6: ← pick Custom in the menu, then type your rate in the teal box
A7: Higher duties | B7: Auto | C7: =IF(OR(HDCode="None",HDCode="Custom",HDCode=""),"",IFERROR(INDEX(PayScaleRates,MATCH(HDCode,PayScaleNames,0),IF($B$5="Casual",2,1)),"")) -> 43.77632 | E7: ← custom HD rate goes in the teal box · Auto follows your classification (L3/L4 → L5-1, L5 → L6-1) · None = not acting
A8: Shift allowance class | B8: Auto | D8: Auto follows your classification: OO3-OO5 = 26.96% · OO6 = 27.46%
A9: Shift class — higher duties | B9: Auto | D9: Auto follows the HD level: OO6 = 27.46%, everything else (Custom included) = 26.96%
A10: TSV location allowance | B10: None | D10: Townsville-based? Pick Half (no dependants) or Full (with dependants). Everyone else leave on None. Casuals get none.
A11: Retention allowance | B11: Yes | D11: per ordinary hour · rate lives on the Settings & Rates tab
A12: Qualification | D12: Now part of your classification. Payroll folds the EBA cl 4.2 allowance into the rate instead of paying it as its own line, so pick L3-Q, L4-Q, L5-Q or L6-Q in the Classification box above. There is no separate setting any more.
A13: In-charge nights | D13: OPS1 on night shift is entitled to the in-charge allowance · $16.39 per shift — rate on Settings & Rates
A14: ▸ Paid leave this fortnight | C14: No leave | E14: =IF(AND(N($B$14)>0,$C$14="No leave"),"⚠ pick a leave type",IF(LeaveHrs=0,"",TEXT(LeavePay,"$#,##0.00")&" at base")) | F14: hours + type · pays base rate; which allowances keep paying depends on the leave type — the Pay Guide tab has the full breakdown
A15: ▸ Public holidays on your RDO | E15: =IF($B$15="","",IF($B$5="Casual","⚠ casuals are not entitled (award cl 23.4)",TEXT($B$15*Hrs_PHRDO,"0.0")&" hrs at base")) | F15: days · award cl 23.4 pays an extra day's wage (7.6 hrs at ordinary rates) for each public holiday that falls on a rostered day off — permanent only; part-timers set their own hours/day on Settings & Rates
A16: ② TIMESHEET — enter hours | G16: columns F–I = higher-duties hours
A17: Day | B17: Ordinary ×1 | C17: Overtime ×2 | D17: Pub hol ×2.5 | E17: Quad ×4 | F17: HD Ord ×1 | G17: HD OT ×2 | H17: HD PH ×2.5 | I17: HD Quad ×4 | J17: Day pay
A18: Mon · W1 | J18: =SUMPRODUCT($B18:$E18,{1,2,2.5,4})*BaseRate+SUMPRODUCT($F18:$I18,{1,2,2.5,4})*HDRate -> 0
A19: Tue · W1 | J19: =SUMPRODUCT($B19:$E19,{1,2,2.5,4})*BaseRate+SUMPRODUCT($F19:$I19,{1,2,2.5,4})*HDRate -> 0
A20: Wed · W1 | J20: =SUMPRODUCT($B20:$E20,{1,2,2.5,4})*BaseRate+SUMPRODUCT($F20:$I20,{1,2,2.5,4})*HDRate -> 0
A21: Thu · W1 | J21: =SUMPRODUCT($B21:$E21,{1,2,2.5,4})*BaseRate+SUMPRODUCT($F21:$I21,{1,2,2.5,4})*HDRate -> 0
A22: Fri · W1 | J22: =SUMPRODUCT($B22:$E22,{1,2,2.5,4})*BaseRate+SUMPRODUCT($F22:$I22,{1,2,2.5,4})*HDRate -> 0
A23: Sat · W1 | J23: =SUMPRODUCT($B23:$E23,{1,2,2.5,4})*BaseRate+SUMPRODUCT($F23:$I23,{1,2,2.5,4})*HDRate -> 0
A24: Sun · W1 | J24: =SUMPRODUCT($B24:$E24,{1,2,2.5,4})*BaseRate+SUMPRODUCT($F24:$I24,{1,2,2.5,4})*HDRate -> 0
A25: Mon · W2 | J25: =SUMPRODUCT($B25:$E25,{1,2,2.5,4})*BaseRate+SUMPRODUCT($F25:$I25,{1,2,2.5,4})*HDRate -> 0
A26: Tue · W2 | J26: =SUMPRODUCT($B26:$E26,{1,2,2.5,4})*BaseRate+SUMPRODUCT($F26:$I26,{1,2,2.5,4})*HDRate -> 0
A27: Wed · W2 | J27: =SUMPRODUCT($B27:$E27,{1,2,2.5,4})*BaseRate+SUMPRODUCT($F27:$I27,{1,2,2.5,4})*HDRate -> 0
A28: Thu · W2 | J28: =SUMPRODUCT($B28:$E28,{1,2,2.5,4})*BaseRate+SUMPRODUCT($F28:$I28,{1,2,2.5,4})*HDRate -> 0
A29: Fri · W2 | J29: =SUMPRODUCT($B29:$E29,{1,2,2.5,4})*BaseRate+SUMPRODUCT($F29:$I29,{1,2,2.5,4})*HDRate -> 0
... A31: Sun · W2 | J31: =SUMPRODUCT($B31:$E31,{1,2,2.5,4})*BaseRate+SUMPRODUCT($F31:$I31,{1,2,2.5,4})*HDRate -> 0
A32: Hours / totals | B32: =IF(SUM(B18:B31)>0,SUM(B18:B31),N($C$33)) -> 76 | C32: =SUM(C18:C31) -> 0 | D32: =SUM(D18:D31) -> 0 | E32: =SUM(E18:E31) -> 0 | F32: =SUM(F18:F31) -> 0 | G32: =SUM(G18:G31) -> 0 | H32: =SUM(H18:H31) -> 0 | I32: =SUM(I18:I31) -> 0 | J32: =SUM(J18:J31) -> 0
A33: Or quick-fill ordinary hrs → | C33: 76 | D33: =SUM($B$32:$I$32) -> 76 | F33: =IF(N($C$33)>0,"quick-fill "&TEXT($C$33,"0")&" ordinary hrs"&IF(SUM($F$32:$I$32)>0," + "&TEXT(SUM($F$32:$I$32),"0")&" HD hrs from the grid = "&TEXT($C$33+SUM($F$32:$I$32),"0")&" paid"," · add overtime, penalties or HD hours in the grid"),"ordinary "&TEXT($B$32,"0.0")&" · higher duties "&TEXT(SUM($F$32:$I$32),"0.0"))&IF(LeaveHrs>0," · paid leave "&TEXT(LeaveHrs,"0.0"),"") -> quick-fill 76 ordinary hrs · add overtime, penalties or HD hours in the grid
A34: ③ YOUR PAY
A35: NET IN BANK — this fortnight | F35: =$J$66-$J$67-$J$68-$J$69-$J$70-$J$71 -> 2974.1488
A38: GROSS — THIS FORTNIGHT | D38: GROSS / HOUR | F38: NET (BANK) / HOUR | H38: ANNUAL NET (EST.) | J38: EFFECTIVE TAX RATE
A39: =$J$58 -> 4048.6488 | D39: =IF((SUM($B$32:$I$32)+LeaveHrs)=0,0,$J$58/(SUM($B$32:$I$32)+LeaveHrs)) -> 53.271695 | F39: =IF((SUM($B$32:$I$32)+LeaveHrs)=0,0,NetBank/(SUM($B$32:$I$32)+LeaveHrs)) -> 39.133537 | H39: =NetBank*FnPerYear -> 77327.869 | J39: =IF($J$66=0,0,$J$67/$J$66) -> 0.23020026
A42: ④ EARNINGS
A43: Ordinary time & paid leave | F43: =TEXT($B$32,"0.0")&" hrs × "&TEXT(BaseRate,"$0.00")&IF(LeaveHrs>0," + "&TEXT(LeaveHrs,"0.0")&" leave hrs @ base","") -> 76.0 hrs × $37.50 | J43: =$B$32*BaseRate+LeavePay -> 2850
A44: Overtime | F44: =TEXT($C$32,"0.0")&" hrs × "&TEXT(BaseRate*2,"$0.00") -> 0.0 hrs × $75.00 | J44: =$C$32*2*BaseRate -> 0
A45: Public holiday | F45: =TEXT($D$32,"0.0")&" hrs × "&TEXT(BaseRate*2.5,"$0.00") -> 0.0 hrs × $93.75 | J45: =$D$32*2.5*BaseRate -> 0
...

Sheet Pay Guide
A1: PAY GUIDE
A2: How your pay actually works — real rates, what applies when, and where each rule comes from (award = YDC Award 2016 · EBA = CB/2023/139)
A4: ① HOW A FORTNIGHT’S PAY COMES TOGETHER
A5: Base pay | B5: Rostered hours × your hourly rate. A full-time fortnight is 76 ordinary hours — most of the flat allowances pro-rata against that number.
A6: Allowances | B6: Stack on top of base for the conditions of the job. Two kinds: percentage (shift allowance, on your ordinary earnings) and flat (TSV, operational, retention, laundry — per ordinary hour, capped at the 76-hour full-fortnight value).
A7: Gross vs taxable | B7: Gross is everything before deductions. Anything salary-sacrificed comes off BEFORE tax, so taxable income can be lower than gross — that gap is where packaging saves you money.
A8: Tax & deductions | B8: PAYG withholding, any study-loan slice, then after-tax items like the standard member super. What’s left is net in bank.
A9: Award vs EBA | B9: You’re paid whichever is better — the agreement can’t pay under the parent award (EBA cl 2.18(6)). Since the 2026 State Wage Case the award rates sit about 6.3% ABOVE the EBA’s final rates, so the award is currently what you’re actually paid.
A11: ② THE ALLOWANCES — WHAT, HOW MUCH, WHEN
A12: Consolidated shift allowance (CSA) | B12: 26.96% for OO3–OO5, 27.46% for OO6, on ordinary-time earnings (EBA cl 2.9(4)). It replaces night/weekend penalties because the 12-hour roster covers all hours. NOT paid on overtime or public-holiday penalty hours (cl 2.9(6)) — those already carry their own multiplier.
A13: TSV locality | B13: Townsville rate: $43.40/fn with dependants, $21.70/fn without (Directive 16/18). Townsville-based permanent staff only — casuals get none, and staff based elsewhere (e.g. Brisbane secondees) get none: set TSV to None. Keeps being paid through paid leave.
A14: Operational | B14: $4.9867 per ordinary hour, capped at $379.00/fn — near enough to 76 hours’ worth ($378.99), so the cap only bites once leave or higher-duties hours push you past 76 (EBA cl 2.10(3)). Recognises the operational nature of the role. Paid on annual, long service and special leave, but NOT sick leave (cl 2.10(4)–(5)).
A15: Retention | B15: $45.00/fn (= $0.5921/hr × 76) once you’ve done 2 years’ continuous service (EBA cl 2.12). Doesn’t index with pay rises (cl 2.12(5)). Keeps being paid on all paid leave, sick included. Note: on paper it’s all-purpose (cl 2.12(2)(i) — ‘subject to any applicable overtime or penalty rates’); the calculator pays it flat to 76 hours, matching the payslip element "YD Retent 76", so on an overtime-heavy fortnight it’s worth checking with a delegate.
A16: Laundry | B16: $6.30/fn spread across ordinary hours (Award cl 13.6(b)). It is an expense allowance, so it moves with CPI rather than with the State Wage Case (cl 13.7(b)). Only for hours actually worked — no shifts, no washing, no allowance.
A17: Qualification | B17: Worth $41.50 (OO3) · $42.80 (OO4/OO5) · $44.60 (OO6) a fortnight (EBA cl 4.2), once you have held the top paypoint of your level for 12 months. Casuals take longer: a calendar year AND 1,200 hours at the top paypoint (cl 4.1(c)). There is no separate setting for it — payroll folds it into your rate and stores the result as one classification, so pick L3-Q, L4-Q, L5-Q or L6-Q in the Classification box. Inside the rate it is pro-rated by the hours you work, picks up the casual 25% loading and counts toward the shift allowance, which is worth a little more than being paid flat.
A18: In-charge | B18: $16.39 per shift for the shift supervisor when most of the shift falls outside 0830–1700 — in practice, OPS1 on nights (Award cl 13.2).
A19: Other taxable earnings | B19: A flexible taxable line for anything not covered above — most commonly a secondee travel/meal allowance for Brisbane staff working in TSV, but usable for any taxable one-off. You type the amount (on the calculator, on the In-charge row). It is added to gross and taxed as wages, but excluded from the super base (it is not ordinary-time earnings). If your payment is instead a genuine tax-free reimbursement, it does not belong anywhere in this workbook — leave it out entirely.
A21: ③ PENALTIES & EXTRAS
A22: Overtime | B22: Hours beyond the rostered shift at ×2 (Award cl 18). No CSA on top — the double rate IS the compensation.
A23: Public holidays worked | B23: ×2.5 for working the day itself (Award cl 23.1), with a 4-hour minimum: for a short call-in, enter at least 4 hours in the grid even if you worked less. The calculator uses raw hours, so entering the minimum is how you capture it.
A24: Quad time | B24: ×4 — the ceiling rate, mainly overtime worked on a public holiday.
A25: Higher duties | B25: Acting at a higher classification pays that classification’s rate for the hours acted, penalties included — that’s what timesheet columns F–I are for. When it kicks in (cl 12.7): after one full shift for Youth Worker→Section Supervisor and Section→Shift Supervisor; after more than 3 consecutive days for other combinations. HD pays the FIRST paypoint of the higher level.
A26: Public holiday on your RDO | B26: A public holiday landing on a rostered day off pays an EXTRA day’s wage — 7.6 hrs at ordinary rates for full-timers, your usual day for part-timers (Award cl 23.4). Permanents only; you can’t also claim a substituted holiday for the same day.
A27: Casual loading | B27: 25% on top of the permanent rate (Award cl 8.3(c)), paid INSTEAD of annual and sick leave, notice and redundancy. It’s part of your ordinary rate, so shift allowance and super are calculated on the loaded rate.
A28: Minimum engagements | B28: Casual and part-time engagements carry a 2-hour minimum (Award cl 8.2(c), 8.3(d)); recall to duty pays a 2-hour minimum at overtime rates (cl 18.4). Ordinary overtime has no minimum — double time for the hours you actually work (cl 18.3). The calculator takes raw hours — enter the minimum, not the shorter time worked.
A30: ④ LEAVE — WHAT YOU KEEP, WHAT STOPS
A31: Annual & long service | B31: Base rate for your rostered hours — continuous shift workers accrue five weeks’ rec leave a year (20 days plus an extra week for continuous shift workers — Dir 11/24 Sch 1 cl 2.1; 25 days outright in the Northern/Western region). KEEPS: shift allowance through both rec leave AND long service leave — paid in lieu of the award’s leave loading (EBA cl 2.9(5)), and at 26.96–27.46% it’s worth more than the loading it replaces. Also keeps operational (cl 2.10(5)), retention (cl 2.12) and TSV (Directive 16/18). DOESN’T GET: laundry or in-charge — those only exist for shifts actually worked, and no separate 17.5% loading on top. A leave fortnight lands within a few dollars of a worked one.
A32: Leave loading — who gets it | B32: You don’t get a separate leave loading, and you’re not missing out — the shift allowance keeps running through recreation and long service leave INSTEAD of one (EBA cl 2.9(5)), and at 26.96–27.46% it comes to more than a loading would. That’s what this workbook pays. A pay summary in July 2026 settled it: the element is named “Consolidated Allow 26.96% WrkRec”, with no separate loading line of any kind.
A33: Sick / carer’s | B33: Base rate. KEEPS: retention and TSV. DOESN’T GET: shift allowance (EBA cl 2.9(6)(iv)), operational (cl 2.10(4)(iii)) or laundry — the on-shift allowances stop when you’re not on shift, so a sick fortnight pays noticeably less than a worked one.
A34: Special (paid) | B34: Base rate. KEEPS: operational, retention, TSV. DOESN’T GET: shift allowance or laundry.
A35: Casuals & leave | B35: Normally no paid leave — the 25% loading is the trade (Award cl 8.3(e)). Long service leave is the real exception: expressly extended to casuals (Award cl 8.3(h) and cl 22(a)) and paid at the loaded casual rate. Special leave is a different case — you are probably NOT entitled to it: the paid entitlement exists only under Special Leave Directive 12/24, whose cl 4.2 says the directive does not apply to casual employees except for unpaid Bereavement and unpaid Compassionate Leave. It is still accepted here and on the website because it does occasionally get approved and paid anyway, so a payslip showing it can be reconciled — but do not plan on it. Check your own entitlement before relying on a leave figure. Note: as at 26.07.2026 this workbook matches the website — pick Casual and the sick/carer's and annual boxes pay nothing, while long service and special leave still pay at the loaded casual rate.
A37: ⑤ TAX & SUPER
A38: PAYG withholding | B38: ATO Schedule 1 coefficients (tables dated 01.07.2026), applied per fortnight. Scale 2 = tax-free threshold claimed, which is normal for your main job. It’s a per-pay estimate — the true figure settles at your return.
A39: Study loans (HELP/STSL) | B39: ATO Schedule 8 — nothing withheld until taxable pay reaches about $2,674/fn (threshold claimed), then a marginal slice on top. Heads-up: salary sacrificing lowers the fortnightly STSL withheld but NOT the annual repayment (repayment income adds sacrificed super back), so heavy sacrificing with a HELP debt can mean a tax-time catch-up.
A40: Salary sacrifice — no gross-up | B40: Sacrificed super is taxed 15% inside the fund, so a 5% sacrifice only lands 4.25%. Payroll does NOT top that up for you — a payslip we checked deducted exactly 5.00% of the fortnightly salary, not 5.88%. If you want a full 5% to land, set the member rate to 5.88% yourself (5 ÷ 0.85). Sacrificing is still ahead of paying it after tax, because it leaves your pay before income tax does.
A41: Concessional cap | B41: Employer contributions + everything salary-sacrificed count toward $32,500/yr (FY2026-27). After-tax member contributions don’t. The super section tracks your headroom automatically.
A42: Employer super | B42: 12.75% of ordinary-time earnings — ordinary hours, shift allowance, ordinary-time allowances (laundry included), paid leave and public holidays you work; overtime excluded (Superannuation (State Public Sector) Regulation 2023). Paid whether or not you make the member contribution.
A43: Member 5% | B43: The standard employee contribution for permanents — after-tax by default, or packaged pre-tax through RemServ. Casuals default to 0%.
A45: ⑥ GOOD TO KNOW
A46: Backpay & manual payments | B46: Lump sums (backpay, missed shifts paid late, corrections) are withheld using the ATO’s lump-sum method — roughly, taxed as if you earned that much every fortnight — so the payment usually looks overtaxed on the day. The overs come back at your tax return; nothing is lost, just early.
...

Sheet Settings & Rates
A1: SETTINGS & RATE LIBRARY
A2: Blue-on-yellow cells are the ones you edit. Everything on the calculator reads from here. | sheets are protected — password: paycalc (Review → Unprotect Sheet)
A4: A · PAY SCALE — QLD Operational Officers, effective 01.09.2026 | F4: Source: QIRC 01.09.2026 award reprint (matter B/2026/59-60, incl. 1 Sep 2026 General Ruling, +4.75%; on pay from 28.10.2026). All 15 rows round exactly to the reprint fortnightly $ — see block E
A5: Classification | B5: Permanent $/hr | C5: Casual $/hr | D5: Salary / f'night
A6: L3-1 | B6: 35.31579 | C6: =B6*1.25 -> 44.144737 | D6: =B6*76 -> 2684
A7: L3-2 | B7: 35.98684 | C7: =B7*1.25 -> 44.98355 | D7: =B7*76 -> 2734.9998
A8: L3-3 | B8: 36.75 | C8: =B8*1.25 -> 45.9375 | D8: =B8*76 -> 2793
A9: L3-4 | B9: 37.5 | C9: =B9*1.25 -> 46.875 | D9: =B9*76 -> 2850
A10: L4-1 | B10: 39.01316 | C10: =B10*1.25 -> 48.76645 | D10: =B10*76 -> 2965.0002
A11: L4-2 | B11: 40.25 | C11: =B11*1.25 -> 50.3125 | D11: =B11*76 -> 3059
A12: L4-3 | B12: 41.5 | C12: =B12*1.25 -> 51.875 | D12: =B12*76 -> 3154
A13: L4-4 | B13: 42.69737 | C13: =B13*1.25 -> 53.371713 | D13: =B13*76 -> 3245.0001
A14: L5-1 | B14: 43.77632 | C14: =B14*1.25 -> 54.7204 | D14: =B14*76 -> 3327.0003
A15: L5-2 | B15: 45.15789 | C15: =B15*1.25 -> 56.447363 | D15: =B15*76 -> 3431.9996
A16: L5-3 | B16: 46.60526 | C16: =B16*1.25 -> 58.256575 | D16: =B16*76 -> 3541.9998
A17: L5-4 | B17: 48 | C17: =B17*1.25 -> 60 | D17: =B17*76 -> 3648
... A20: L6-3 | B20: 52.60526 | C20: =B20*1.25 -> 65.756575 | D20: =B20*76 -> 3997.9998
A21: Award rates, effective 01.09.2026 — verified against the QIRC 01.09.2026 award reprint (all 15 rows round exactly to the published fortnightly $). Hourly = fortnightly ÷ 76; casual = permanent × 1.25 (all three columns reconcile exactly). The fortnightly salary is a whole dollar: each wage case applies its rise to the old whole-dollar salary and rounds back to the nearest dollar — the 2026 case was 4.75%, e.g. L4-4 $3,098 → $3,245.155 → $3,245 → $42.69737/hr. Payroll starts paying these from 28.10.2026, so earlier payslips show the 2025 rates. The rounding was cross-checked against a real payslip at the 2025 rates (11–24 Jul 2026: L4-4 $40.76316, L5-1 $41.78947 — both exact); the 2026 rates haven’t met a payslip yet. Keep the rounding when the next wage case lands. The award floor sits about 6.3% above the 01.08.2025 EBA rates and prevails under EBA cl 2.18(6). Custom rates are typed straight on the calculator. Update when the new agreement or the 2027 State Wage Case lands — see block E.
A23: B · ALLOWANCE RATES
A24: Allowance | B24: Rate | C24: Unit / basis | F24: Notes
A25: Consolidated shift — class OO3–OO5 | B25: 0.2696 | C25: % of ordinary earnings | F25: EBA cl 2.9(4)(i)–(ii) — 12-hour continuous shift workers, OO3/OO4/OO5. Consolidates afternoon/night loadings and weekend penalties.
A26: Consolidated shift — class OO6 | B26: 0.2746 | C26: % of ordinary earnings | F26: EBA cl 2.9(4)(iii) — OO6. Also the default for higher-duties hours at OO6.
A27: TSV location — full rate | B27: 0.571053 | C27: $ / ordinary hour | F27: Directive 16/18 (Locality Allowances) — Townsville $43.40/fn ÷ 76. Full rate needs dependants; Townsville is coastal so the EBA cl 2.8(2) +5.5% does not apply.
A28: TSV location — half rate | B28: 0.28553 | C28: $ / ordinary hour | F28: Directive 16/18 — Townsville $21.70/fn ÷ 76. Continues during paid leave (the calculator includes leave hours). Casual employees are not eligible (handled automatically).
A29: Operational employee | B29: 4.9867 | C29: $ / ordinary hour | F29: EBA cl 2.10(3)(ii) — rate from 01.08.2025 (prev. 4.8415), max $379.00/fn = 76 ordinary hours (the calculator caps at 76). Set the rate to 0 to switch off.
A30: Retention | B30: 0.5921 | C30: $ / ordinary hour | F30: EBA cl 2.12 — $45.00/fn ÷ 76, after 2 years' service. Applied to ordinary hours up to 76 — confirmed by a real payslip, where the element is literally named "YD Retent 76" and pays $0.59210/hr on hours worked. Casuals get it pro-rata (EBA cl 2.12(4)). Yes/No toggle lives on the calculator page.
A31: Laundry | B31: 0.082895 | C31: $ / ordinary hour | F31: Award cl 13.6(b) — $6.30/fn ÷ 76, CPI-adjusted at the 01.09.2026 reprint (was $6.10). Set 0 to switch off. (Separate soiled-linen allowance cl 2.11 is out of scope — it applies to OO2 Laundry Assistant / OO3 Laundry Supervisor roles only, not operational shiftworkers.)
A32: In-charge | B32: 16.39 | C32: $ / night | F32: Award cl 13.2 — shift supervisors where the majority of the shift falls outside 0830–1700. Nights are entered on the calculator page.
A34: C · QUALIFICATION ALLOWANCE ($ per fortnight)
A35: None | B35: 0
A36: Cert IV | B36: 41.5 | F36: Certificate IV (AQF IV) — OO3
A37: Diploma | B37: 42.8 | F37: Diploma (AQF V) — OO4/OO5
A38: Adv Diploma | B38: 44.6 | F38: Advanced Diploma (AQF VI) — OO6
A40: D · SUPER & SYSTEM
A41: Employer super rate | B41: 0.1275 | F41: Superannuation (State Public Sector) Regulation 2023 s 12 — 12.75% of salary, defined as earnings for ordinary hours PLUS shift loadings PLUS payments made on paid leave. Overtime is out. Laundry IS in: on a real payslip (11–24 Jul 2026) the employer contribution came to exactly 12.75% of the full gross, laundry included. The overtime meal allowance is out too — it rides on overtime, so it is not ordinary time earnings. Since 01.07.2023 you receive the full 12.75% whether or not you make the member contribution.
A42: Super contributions tax | B42: 0.15 | F42: Tax the fund deducts from employer and salary-sacrificed (concessional) contributions. After-tax member contributions are NOT taxed in the fund. Payroll does not gross up a sacrificed contribution, so a 5% sacrifice lands 4.25% — set the rate to 5.88% yourself if you want a full 5% in. Study-loan heads-up: sacrificing lowers fortnightly STSL withholding but NOT the annual repayment (repayment income adds sacrificed super back), so expect a small tax-time catch-up if you sacrifice while holding a HELP debt.
A43: SG minimum rate | B43: 0.12 | F43: Commonwealth Superannuation Guarantee floor (12% from 01.07.2025). Reference only — the QLD Gov 12.75% sits above it. It becomes your rate if you are 75 or older.
A44: Concessional contributions cap (p.a.) | B44: 32500 | F44: FY2026-27 cap. Employer + salary-sacrifice count toward it; after-tax member contributions do not.
A45: Standard member contribution — permanent | B45: 0.05 | F45: Default after-tax member rate for permanent staff. Casuals default to 0% on the calculator.
A46: Salary-packaging admin fee (typical) | B46: 1.35 | F46: Only relevant if salary packaging through a provider (e.g. RemServ).
...

Sheet Tax Engine
A1: TAX ENGINE
A2: ATO Schedule-1 coefficient method. Live tables dated 01.07.2026 (FY2026-27). Nothing to edit here.
A4: WITHHOLDING — this fortnight
A5: Taxable income (per fortnight) | B5: ='Pay Calculator'!$J$66 -> 4048.6488 | E5: Resolved base rate → | F5: =IF(OR('Pay Calculator'!$B$6="Custom",'Pay Calculator'!$B$6=""),N('Pay Calculator'!$D$6),IFERROR(INDEX(QScaleRates,MATCH('Pay Calculator'!$B$6,QScaleNames,0),IF('Pay Calculator'!$B$5="Casual",2,1)),IFERROR(INDEX(PayScaleRates,MATCH('Pay Calculator'!$B$6,PayScaleNames,0),IF('Pay Calculator'!$B$5="Casual",2,1)),N('Pay Calculator'!$D$6)))) -> 37.5 | H5: Leave hours → | I5: =IF('Pay Calculator'!$C$14="No leave",0,IF(AND('Pay Calculator'!$B$5="Casual",OR('Pay Calculator'!$C$14="Sick / carer's",'Pay Calculator'!$C$14="Annual / recreation")),0,N('Pay Calculator'!$B$14))) -> 0
A6: Weekly equivalent x = TRUNC(taxable ÷ 2) | B6: =TRUNC(MAX(0,B5)/2,0) -> 2024 | E6: Resolved HD rate → | F6: =IF(HDCode="None",F5,IF(OR(HDCode="Custom",HDCode=""),IF(N('Pay Calculator'!$D$7)>0,N('Pay Calculator'!$D$7),F5),IFERROR(INDEX(PayScaleRates,MATCH(HDCode,PayScaleNames,0),IF('Pay Calculator'!$B$5="Casual",2,1)),N('Pay Calculator'!$D$7)))) -> 43.77632 | H6: Leave pay (base rate) → | I6: =LeaveHrs*BaseRate -> 0
A7: x + 0.99 (ATO rounding convention) | B7: =B6+0.99 -> 2024.99 | E7: Effective tax scale → | F7: =IF(ScaleChoice="Auto","2 - Tax-free threshold claimed",ScaleChoice) -> 2 - Tax-free threshold claimed | H7: Leave carries shift allow.? → | I7: =IF(OR('Pay Calculator'!$C$14="Annual / recreation",'Pay Calculator'!$C$14="Long service"),1,0) -> 0
H8: Leave carries operational? → | I8: =IF(OR('Pay Calculator'!$C$14="Annual / recreation",'Pay Calculator'!$C$14="Long service",'Pay Calculator'!$C$14="Special"),1,0) -> 0
A9: Scale | C9: a | D9: b | F9: Fortnightly tax | H9: Leave carries retention? → | I9: =IF('Pay Calculator'!$C$14="No leave",0,1) -> 0
A10: 1 - No tax-free threshold | C10: =VLOOKUP($B$6,LU_Scale1,2) -> 0.32 | D10: =VLOOKUP($B$6,LU_Scale1,3) -> 71.6508 | F10: =ROUND($B$7*C10-D10,0)*2 -> 1152
A11: 2 - Tax-free threshold claimed | C11: =VLOOKUP($B$6,LU_Scale2,2) -> 0.32 | D11: =VLOOKUP($B$6,LU_Scale2,3) -> 181.7319 | F11: =ROUND($B$7*C11-D11,0)*2 -> 932
A12: 3 - Foreign resident | C12: =VLOOKUP($B$6,LU_Scale3,2) -> 0.3 | D12: =VLOOKUP($B$6,LU_Scale3,3) -> 0.3 | F12: =ROUND($B$7*C12-D12,0)*2 -> 1214
A13: 5 - Full Medicare levy exemption | C13: =VLOOKUP($B$6,LU_Scale5,2) -> 0.3 | D13: =VLOOKUP($B$6,LU_Scale5,3) -> 181.7308 | F13: =ROUND($B$7*C13-D13,0)*2 -> 852
A14: 6 - Half Medicare levy exemption | C14: =VLOOKUP($B$6,LU_Scale6,2) -> 0.31 | D14: =VLOOKUP($B$6,LU_Scale6,3) -> 181.7308 | F14: =ROUND($B$7*C14-D14,0)*2 -> 892
A15: PAYG — selected scale | B15: =ScaleChoice -> Auto | F15: =INDEX($F$10:$F$14,MATCH(ScaleUsed,$A$10:$A$14,0)) -> 932
A17: STSL — TFT claimed / foreign resident | F17: =ROUND($B$7*VLOOKUP($B$6,LU_Scale_HELP_TFTR,2)-VLOOKUP($B$6,LU_Scale_HELP_TFTR,3),0)*2 -> 206
A18: STSL — no tax-free threshold | F18: =ROUND($B$7*VLOOKUP($B$6,LU_Scale_HELP_NTFT,2)-VLOOKUP($B$6,LU_Scale_HELP_NTFT,3),0)*2 -> 312
A19: Study loan this fortnight (0 when toggle = No) | F19: =IF(STSLChoice="Yes",IF(ScaleUsed=$A$10,F18,F17),0) -> 0
A22: WHAT-IF ENGINE — reference only · +1 ordinary hr is cap-aware (flat allowances stop at 76 hrs)
B23: Current | C23: +1 ordinary hr | D23: +1 overtime hr | E23: +1 pub-hol hr | F23: +$100 sal-sac
A24: Δ gross earnings | B24: 0 | C24: =BaseRate*(1+'Pay Calculator'!$G$50)+IF('Pay Calculator'!$B$32<76,('Pay Calculator'!$G$51+'Pay Calculator'!$G$52+'Pay Calculator'!$G$53+'Pay Calculator'!$G$54),0) -> 47.61 | D24: =BaseRate*2 -> 75 | E24: =BaseRate*2.5 -> 93.75 | F24: 0
A25: Δ pre-tax deductions | B25: 0 | C25: 0 | D25: 0 | E25: 0 | F25: 100
A26: Taxable (scenario) | B26: =MAX(0,$B$5+B24-B25) -> 4048.6488 | C26: =MAX(0,$B$5+C24-C25) -> 4096.2588 | D26: =MAX(0,$B$5+D24-D25) -> 4123.6488 | E26: =MAX(0,$B$5+E24-E25) -> 4142.3988 | F26: =MAX(0,$B$5+F24-F25) -> 3948.6488
A27: x = TRUNC(taxable ÷ 2) | B27: =TRUNC(B26/2,0) -> 2024 | C27: =TRUNC(C26/2,0) -> 2048 | D27: =TRUNC(D26/2,0) -> 2061 | E27: =TRUNC(E26/2,0) -> 2071 | F27: =TRUNC(F26/2,0) -> 1974
A28: x + 0.99 | B28: =B27+0.99 -> 2024.99 | C28: =C27+0.99 -> 2048.99 | D28: =D27+0.99 -> 2061.99 | E28: =E27+0.99 -> 2071.99 | F28: =F27+0.99 -> 1974.99
A30: tax @ scale 1 | B30: =ROUND(B$28*VLOOKUP(B$27,LU_Scale1,2)-VLOOKUP(B$27,LU_Scale1,3),0)*2 -> 1152 | C30: =ROUND(C$28*VLOOKUP(C$27,LU_Scale1,2)-VLOOKUP(C$27,LU_Scale1,3),0)*2 -> 1168 | D30: =ROUND(D$28*VLOOKUP(D$27,LU_Scale1,2)-VLOOKUP(D$27,LU_Scale1,3),0)*2 -> 1176 | E30: =ROUND(E$28*VLOOKUP(E$27,LU_Scale1,2)-VLOOKUP(E$27,LU_Scale1,3),0)*2 -> 1182 | F30: =ROUND(F$28*VLOOKUP(F$27,LU_Scale1,2)-VLOOKUP(F$27,LU_Scale1,3),0)*2 -> 1120
A31: tax @ scale 2 | B31: =ROUND(B$28*VLOOKUP(B$27,LU_Scale2,2)-VLOOKUP(B$27,LU_Scale2,3),0)*2 -> 932 | C31: =ROUND(C$28*VLOOKUP(C$27,LU_Scale2,2)-VLOOKUP(C$27,LU_Scale2,3),0)*2 -> 948 | D31: =ROUND(D$28*VLOOKUP(D$27,LU_Scale2,2)-VLOOKUP(D$27,LU_Scale2,3),0)*2 -> 956 | E31: =ROUND(E$28*VLOOKUP(E$27,LU_Scale2,2)-VLOOKUP(E$27,LU_Scale2,3),0)*2 -> 962 | F31: =ROUND(F$28*VLOOKUP(F$27,LU_Scale2,2)-VLOOKUP(F$27,LU_Scale2,3),0)*2 -> 900
A32: tax @ scale 3 | B32: =ROUND(B$28*VLOOKUP(B$27,LU_Scale3,2)-VLOOKUP(B$27,LU_Scale3,3),0)*2 -> 1214 | C32: =ROUND(C$28*VLOOKUP(C$27,LU_Scale3,2)-VLOOKUP(C$27,LU_Scale3,3),0)*2 -> 1228 | D32: =ROUND(D$28*VLOOKUP(D$27,LU_Scale3,2)-VLOOKUP(D$27,LU_Scale3,3),0)*2 -> 1236 | E32: =ROUND(E$28*VLOOKUP(E$27,LU_Scale3,2)-VLOOKUP(E$27,LU_Scale3,3),0)*2 -> 1242 | F32: =ROUND(F$28*VLOOKUP(F$27,LU_Scale3,2)-VLOOKUP(F$27,LU_Scale3,3),0)*2 -> 1184
A33: tax @ scale 5 | B33: =ROUND(B$28*VLOOKUP(B$27,LU_Scale5,2)-VLOOKUP(B$27,LU_Scale5,3),0)*2 -> 852 | C33: =ROUND(C$28*VLOOKUP(C$27,LU_Scale5,2)-VLOOKUP(C$27,LU_Scale5,3),0)*2 -> 866 | D33: =ROUND(D$28*VLOOKUP(D$27,LU_Scale5,2)-VLOOKUP(D$27,LU_Scale5,3),0)*2 -> 874 | E33: =ROUND(E$28*VLOOKUP(E$27,LU_Scale5,2)-VLOOKUP(E$27,LU_Scale5,3),0)*2 -> 880 | F33: =ROUND(F$28*VLOOKUP(F$27,LU_Scale5,2)-VLOOKUP(F$27,LU_Scale5,3),0)*2 -> 822
A34: tax @ scale 6 | B34: =ROUND(B$28*VLOOKUP(B$27,LU_Scale6,2)-VLOOKUP(B$27,LU_Scale6,3),0)*2 -> 892 | C34: =ROUND(C$28*VLOOKUP(C$27,LU_Scale6,2)-VLOOKUP(C$27,LU_Scale6,3),0)*2 -> 906 | D34: =ROUND(D$28*VLOOKUP(D$27,LU_Scale6,2)-VLOOKUP(D$27,LU_Scale6,3),0)*2 -> 914 | E34: =ROUND(E$28*VLOOKUP(E$27,LU_Scale6,2)-VLOOKUP(E$27,LU_Scale6,3),0)*2 -> 922 | F34: =ROUND(F$28*VLOOKUP(F$27,LU_Scale6,2)-VLOOKUP(F$27,LU_Scale6,3),0)*2 -> 862
A35: PAYG (selected scale) | B35: =INDEX(B30:B34,MATCH(ScaleUsed,$A$10:$A$14,0)) -> 932 | C35: =INDEX(C30:C34,MATCH(ScaleUsed,$A$10:$A$14,0)) -> 948 | D35: =INDEX(D30:D34,MATCH(ScaleUsed,$A$10:$A$14,0)) -> 956 | E35: =INDEX(E30:E34,MATCH(ScaleUsed,$A$10:$A$14,0)) -> 962 | F35: =INDEX(F30:F34,MATCH(ScaleUsed,$A$10:$A$14,0)) -> 900
A36: STSL — TFT claimed | B36: =ROUND(B$28*VLOOKUP(B$27,LU_Scale_HELP_TFTR,2)-VLOOKUP(B$27,LU_Scale_HELP_TFTR,3),0)*2 -> 206 | C36: =ROUND(C$28*VLOOKUP(C$27,LU_Scale_HELP_TFTR,2)-VLOOKUP(C$27,LU_Scale_HELP_TFTR,3),0)*2 -> 214 | D36: =ROUND(D$28*VLOOKUP(D$27,LU_Scale_HELP_TFTR,2)-VLOOKUP(D$27,LU_Scale_HELP_TFTR,3),0)*2 -> 218 | E36: =ROUND(E$28*VLOOKUP(E$27,LU_Scale_HELP_TFTR,2)-VLOOKUP(E$27,LU_Scale_HELP_TFTR,3),0)*2 -> 220 | F36: =ROUND(F$28*VLOOKUP(F$27,LU_Scale_HELP_TFTR,2)-VLOOKUP(F$27,LU_Scale_HELP_TFTR,3),0)*2 -> 192
A37: STSL — no TFT | B37: =ROUND(B$28*VLOOKUP(B$27,LU_Scale_HELP_NTFT,2)-VLOOKUP(B$27,LU_Scale_HELP_NTFT,3),0)*2 -> 312 | C37: =ROUND(C$28*VLOOKUP(C$27,LU_Scale_HELP_NTFT,2)-VLOOKUP(C$27,LU_Scale_HELP_NTFT,3),0)*2 -> 318 | D37: =ROUND(D$28*VLOOKUP(D$27,LU_Scale_HELP_NTFT,2)-VLOOKUP(D$27,LU_Scale_HELP_NTFT,3),0)*2 -> 322 | E37: =ROUND(E$28*VLOOKUP(E$27,LU_Scale_HELP_NTFT,2)-VLOOKUP(E$27,LU_Scale_HELP_NTFT,3),0)*2 -> 326 | F37: =ROUND(F$28*VLOOKUP(F$27,LU_Scale_HELP_NTFT,2)-VLOOKUP(F$27,LU_Scale_HELP_NTFT,3),0)*2 -> 296
A38: STSL (selected) | B38: =IF(STSLChoice="Yes",IF(ScaleUsed=$A$10,B37,B36),0) -> 0 | C38: =IF(STSLChoice="Yes",IF(ScaleUsed=$A$10,C37,C36),0) -> 0 | D38: =IF(STSLChoice="Yes",IF(ScaleUsed=$A$10,D37,D36),0) -> 0 | E38: =IF(STSLChoice="Yes",IF(ScaleUsed=$A$10,E37,E36),0) -> 0 | F38: =IF(STSLChoice="Yes",IF(ScaleUsed=$A$10,F37,F36),0) -> 0
A39: Δ after-tax member super | B39: 0 | C39: =MemberPct*BaseRate -> 1.875 | D39: 0 | E39: 0 | F39: 0
A40: Δ NET IN BANK vs current | B40: =(B26-$B$26)-(B35-$B$35)-(B38-$B$38)-B39 -> 0 | C40: =(C26-$B$26)-(C35-$B$35)-(C38-$B$38)-C39 -> 29.735 | D40: =(D26-$B$26)-(D35-$B$35)-(D38-$B$38)-D39 -> 51 | E40: =(E26-$B$26)-(E35-$B$35)-(E38-$B$38)-E39 -> 63.75 | F40: =(F26-$B$26)-(F35-$B$35)-(F38-$B$38)-F39 -> -68
A43: REFERENCE LIBRARY — scales 1/2/3/5/6 and STSL are live ATO tables dated 01.07.2026; the rest are V16.2 reference (2024-25)
A44: Named ranges below cover only the sorted numeric rows, so VLOOKUP behaves identically in Excel and LibreOffice.
A46: Scale1 | B46: (named range: LU_Scale1)
A47: $ (weekly) | B47: a | C47: b
A48: 0 | B48: 0.15 | C48: 0.15
...
